{"tag": "function", "depth": 1, "time": 1715011423.077641, "data": {"name": "connect_device", "call_args": {"uri": "android://127.0.0.1:5037/NDF0217B10002156?cap_method=JAVACAP&&ori_method=MINICAPORI&&touch_method=MINITOUCH"}, "start_time": 1715011418.046613, "traceback": "Traceback (most recent call last):\n  File \"/opt/anaconda3/envs/en_conda1/lib/python3.8/site-packages/airtest/core/android/adb.py\", line 340, in wait_for_device\n    self.cmd(\"wait-for-device\", timeout=timeout)\n  File \"/opt/anaconda3/envs/en_conda1/lib/python3.8/site-packages/airtest/core/android/adb.py\", line 220, in cmd\n    stdout, stderr = proc_communicate_timeout(proc, timeout)\n  File \"/opt/anaconda3/envs/en_conda1/lib/python3.8/site-packages/airtest/utils/compat.py\", line 79, in proc_communicate_timeout\n    raise_from(exp, None)\n  File \"<string>\", line 3, in raise_from\nRuntimeError: Command ['/Applications/AirtestIDE.app/Contents/MacOS/airtest/core/android/static/adb/mac/adb', '-P', '5037', '-s', 'NDF0217B10002156', 'wait-for-device'] timed out after 5 seconds: stdout['b'''], stderr['b''']\n\nThe above exception was the direct cause of the following exception:\n\nTraceback (most recent call last):\n  File \"/opt/anaconda3/envs/en_conda1/lib/python3.8/site-packages/airtest/utils/logwraper.py\", line 131, in wrapper\n    res = f(*args, **kwargs)\n  File \"/opt/anaconda3/envs/en_conda1/lib/python3.8/site-packages/airtest/core/api.py\", line 74, in connect_device\n    dev = init_device(platform, uuid, **params)\n  File \"/opt/anaconda3/envs/en_conda1/lib/python3.8/site-packages/airtest/core/api.py\", line 42, in init_device\n    dev = cls(uuid, **kwargs)\n  File \"/opt/anaconda3/envs/en_conda1/lib/python3.8/site-packages/airtest/core/android/android.py\", line 59, in __init__\n    self.adb.wait_for_device()\n  File \"/opt/anaconda3/envs/en_conda1/lib/python3.8/site-packages/airtest/core/android/adb.py\", line 342, in wait_for_device\n    raisefrom(DeviceConnectionError, \"device not ready\", e)\n  File \"/opt/anaconda3/envs/en_conda1/lib/python3.8/site-packages/airtest/utils/compat.py\", line 55, in raisefrom\n    raise_from(exc_type(message), exc)\n  File \"<string>\", line 3, in raise_from\nairtest.core.error.DeviceConnectionError: 'device not ready'\n", "end_time": 1715011423.077575}}
